# python asyncio ensure_future()で外で実行されたコードの例外の表示

`Ctrl + c` 今のところSIGINTで中断させないと見れなそうな感じ。


# python asyncioむずかし
